Workbook

Sheet Toelichting model
A1: Deze rekensheet is een overzicht van de gewichtverdeling van de gehele boerderij
A2: Datum balans opmaak: 7-3-2025
A4: Blad verdieping 1, 0 en -1
A5: Het raster is gemaakt op basis van de bouwtechnische indeling
A6: In de momentenbalans is de zwaartekrachtversnelling g niet meegenomen, immers is deze over de gehele boerderij constant.
A7: Per vak zijn alle onderdelen aangegeven, met daarbij een inschatting van de grootte van de massa in kilogram. De inschatting is waar mogelijk gedaan op basis van beschikbare data sheets en machine specificaties.
A8: De groene tekstkleur zijn onderdelen met variërende massa's
A9: De eenheid van de getallen is kilogram
A11: Blad belastingverdeling
A12: Op dit blad is de verdeling van alle belastingen weergeven per rastervak per verdieping.
A13: De eenheid van de getallen is kilogram
A15: Bladen momentverdeling horizontale en verticale as
... A17: De eenheid van de weergegeven getallen is kg*m. Dit is afwijkend van de standaard eenheid Nm, doordat de zwaartekrachtsversnelling niet is meegenomen in de berekening. De zwaartekrachtsversnelling is immers overal constant

Sheet Verdieping 1
A1: VERDIEPING 1 | C1: Gem | D1: Max | E1: Min | H1: Gem | I1: Max | J1: Min | M1: Gem | N1: Max | O1: Min
A2: A1 | B2: 1x IBC vol | C2: 1000 | D2: =C2 -> 1000 | E2: =C2 -> 1000 | F2: D1 | K2: G1
B3: 2x ton krachtvoer | C3: 100 | D3: 150 | E3: 50
A4: A2 | B4: droogvoer bak | C4: 100 | D4: 100 | E4: 100 | F4: D2 | K4: G2 | L4: voerband | M4: 700 | N4: =M4 -> 700 | O4: =M4 -> 700
A6: A3 | F6: D3 | K6: G3 | L6: 2x ton zaagsel en kalk | M6: 50 | N6: 75 | O6: 0
L7: sparing voerband 1,5x1m met voerband | M7: =((1.5*1*0.05)*C54)+M4 -> 512.5 | N7: =M7 -> 512.5 | O7: =M7 -> 512.5
A8: A4 | F8: D4 | K8: G4 | L8: melkrobot hekwerk | M8: 50 | N8: =M8 -> 50 | O8: =M8 -> 50
A10: A5 | F10: D5 | K10: G5 | L10: melkrobot hekwerk | M10: 50 | N10: =M10 -> 50 | O10: =M10 -> 50
A12: A6 | F12: D6 | K12: G6 | L12: sparing voerband 1,5x1m met voerband | M12: =M7 -> 512.5 | N12: =M7 -> 512.5 | O12: =M7 -> 512.5
A14: A7 | F14: D7 | K14: G7 | L14: voerband | M14: =M4 -> 700 | N14: =M4 -> 700 | O14: =M4 -> 700
L15: sparing mestput 1x0,5m | M15: =(1*0.5*0.05)*C54 -> -62.5 | N15: =M15 -> -62.5 | O15: =M15 -> -62.5
A16: A8 | B16: 1x IBC vol | C16: 1000 | D16: =C16 -> 1000 | E16: =C16 -> 1000 | F16: D8 | K16: G8 | L16: sparing paal d1,420 | M16: =C32 -> -197.95961 | N16: =M16 -> -197.95961 | O16: =M16 -> -197.95961
A18: B1 | F18: E1 | K18: H1 | L18: Houten wand | M18: =(0.03*3.75*2.5)*460 -> 129.375 | N18: =M18 -> 129.375 | O18: =M18 -> 129.375
A20: B2 | F20: E2 | K20: H2 | L20: Houten wand | M20: =(0.03*3.75*2.5)*460 -> 129.375 | N20: =M20 -> 129.375 | O20: =M20 -> 129.375
A22: B3 | F22: E3 | K22: H3 | L22: Houten wand | M22: =(0.03*3.75*2.5)*460 -> 129.375 | N22: =M22 -> 129.375 | O22: =M22 -> 129.375
A24: B4 | F24: E4 | K24: H4 | L24: melkrobot installatie | M24: 75 | N24: =M24 -> 75 | O24: =M24 -> 75
L25: Houten wand | M25: =(0.03*3.75*2.5)*460 -> 129.375 | N25: =M25 -> 129.375 | O25: =M25 -> 129.375
A26: B5 | F26: E5 | K26: H5 | L26: compressor uierreiningingstank d0,4 x1m | M26: =((((0.4^2)*PI()/4)*1)*1000*0.6)+50 -> 125.39822 | N26: =((((0.4^2)*PI()/4)*1)*1000)+50 -> 175.66371 | O26: =20+50 -> 70
L27: Houten wand | M27: =(0.03*3.75*2.5)*460 -> 129.375 | N27: =M27 -> 129.375 | O27: =M27 -> 129.375
A28: B6 | F28: E6 | K28: H6 | L28: Houten wand | M28: =(0.03*3.75*2.5)*460 -> 129.375 | N28: =M28 -> 129.375 | O28: =M28 -> 129.375
A30: B7 | F30: E7 | K30: H7 | L30: Houten wand | M30: =(0.03*3.75*2.5)*460 -> 129.375 | N30: =M30 -> 129.375 | O30: =M30 -> 129.375
A32: B8 | B32: sparing paal d1,420 | C32: =(((1.42^2)*PI()/4)*0.05)*C54 -> -197.95961 | D32: =C32 -> -197.95961 | E32: =C32 -> -197.95961 | F32: E8 | K32: H8 | L32: Houten wand | M32: =(0.03*3.75*2.5)*460 -> 129.375 | N32: =M32 -> 129.375 | O32: =M32 -> 129.375
A34: C1 | B34: Brug | C34: 1300 | D34: =C34 -> 1300 | E34: =C34 -> 1300 | F34: F1
A36: C2 | F36: F2
A38: C3 | F38: F3
A40: C4 | F40: F4 | G40: alle koeien | H40: =600*31 -> 18600 | I40: =H40 -> 18600 | J40: =I40 -> 18600
A42: C5 | F42: F5
A44: C6 | F44: F6
A46: C7 | F46: F7
A48: C8 | F48: F8
B51: OPMERKINGEN / AANVULLENDE GEGEVENS | G51: BELASTING OVER MEERDERE VAKKEN
B52: Stal indeling in beide inrichtingen uniform | F52: H | G52: Plankenmuur h 4m
F53: D1 tm G1 | G53: Voer
B54: Dikte stalvloer 5cm [kg/m3] | C54: -2500 | F54: D2 tm G2 | G54: Koeien
F55: C8 tm G8 | G55: Voer
F56: C7 tm G7 | G56: koeien

Sheet Verdieping 0
A1: VERDIEPING 0 | C1: Gem | D1: Max | E1: Min | H1: Gem | I1: Max | J1: Min | M1: Gem | N1: Max | O1: Min
A2: A1 | F2: D1 | K2: G1 | L2: afval container groot + klein | M2: =100+30 -> 130 | N2: =150+50 -> 200 | O2: =70+10 -> 80
A4: A2 | F4: D2 | K4: G2 | L4: 4x grijze kist | M4: 400 | N4: =4*150 -> 600 | O4: =0*150 -> 0
A6: A3 | F6: D3 | G6: bezorgboxen opslag | H6: 45 | I6: 50 | J6: 20 | K6: G3 | L6: voerbaal | M6: =500 -> 500 | N6: 800 | O6: 0
G7: 3x wasmachine | H7: 65 | I7: =H7 -> 65 | J7: =H7 -> 65 | L7: voerband | M7: 700
A8: A4 | F8: D4 | G8: koeling | H8: =8*30 -> 240 | I8: =H8 -> 240 | J8: =H8 -> 240 | K8: G4 | L8: voerband | M8: 700
G9: dekvloer | H9: =C41 -> 3515.625 | I9: =D41 -> 3515.625 | J9: =E41 -> 3515.625 | L9: 0,5 combi cutter | M9: =200+300 -> 500 | N9: =200+600 -> 800 | O9: =200 -> 200
A10: A5 | F10: D5 | G10: zuivel | H10: 200 | I10: =H10 -> 200 | J10: =H10 -> 200 | K10: G5 | L10: 0,5 combi cutter | M10: =200+300 -> 500 | N10: =200+600 -> 800 | O10: =200 -> 200
G11: dekvloer | H11: =C41 -> 3515.625 | I11: =D41 -> 3515.625 | J11: =E41 -> 3515.625 | L11: voercilo en voerband | M11: =2500+700 -> 3200 | N11: =4500 -> 4500 | O11: =1000 -> 1000
A12: A6 | F12: D6 | G12: opslag zuivel | H12: 250 | I12: =H12 -> 250 | J12: =H12 -> 250 | K12: G6 | L12: ziltinstallatie | M12: 75 | N12: 75 | O12: 75
L13: voerband | M13: 700
A14: A7 | F14: D7 | K14: G7 | L14: mesttrechter 0,5x2m | M14: 250 | N14: 350 | O14: 100
L15: 2x IBC (natte en drogge mest) | M15: =300+300 -> 600 | N15: =400+300 -> 700 | O15: =0+300 -> 300
A16: A8 | F16: D8 | K16: G8
A18: B1 | F18: E1 | K18: H1
A20: B2 | B20: 4x pallet zuivelverpakkingen | C20: 200 | D20: 300 | E20: 50 | F20: E2 | G20: papiercontainer en pallet | H20: 200 | I20: 300 | J20: 100 | K20: H2
G21: lichte staalkast | H21: 60 | I21: =H21 -> 60 | J21: =H21 -> 60
A22: B3 | B22: sparing trap 2,8x1,1m | C22: =2.8*1.1*0.2*C53 -> -1540 | D22: =C22 -> -1540 | E22: =C22 -> -1540 | F22: E3 | G22: 3x regenwater IBC | H22: 2000 | I22: 3200 | J22: 500 | K22: H3
A24: B4 | B24: sparing trap 2,8x1,1m | C24: =2.8*1.1*0.2*C53 -> -1540 | D24: =C24 -> -1540 | E24: =C24 -> -1540 | F24: E4 | G24: koeling | H24: =12*30 -> 360 | I24: =H24 -> 360 | J24: =H24 -> 360 | K24: H4
G25: dekvloer | H25: =C41 -> 3515.625 | I25: =D41 -> 3515.625 | J25: =E41 -> 3515.625
A26: B5 | B26: 2x kast licht | C26: 200 | D26: =C26 -> 200 | E26: =C26 -> 200 | F26: E5 | G26: zuivel | H26: 300 | I26: =H26 -> 300 | J26: =H26 -> 300 | K26: H5 | L26: WR unit | M26: 75 | N26: =M26 -> 75 | O26: =M26 -> 75
G27: dekvloer | H27: =C41 -> 3515.625 | I27: =D41 -> 3515.625 | J27: =E41 -> 3515.625
A28: B6 | B28: sparing lift 2,5x3m | C28: =2.5*3*0.2*C53 -> -3750 | D28: =C28 -> -3750 | E28: =C28 -> -3750 | F28: E6 | G28: 3x installaties met d0,7 x1,2m tank | H28: =150+(0.7*((0.7^2)*PI()/4)*1.2*1000) -> 473.26988 | I28: =150+(((0.7^2)*PI()/4)*1.2*1000) -> 611.81412 | J28: =150+(0.3*((0.7^2)*PI()/4)*1.2*1000) -> 288.54424 | K28: H6 | L28: zonnecel | M28: 30 | N28: =M28 -> 30 | O28: =M28 -> 30
G29: 20x22L jerrycans | H29: =20*22 -> 440 | I29: =H29 -> 440 | J29: =H29 -> 440
A30: B7 | B30: sparing trap 2,8x1,2m | C30: =2.8*1.2*0.2*C53 -> -1680 | D30: =C30 -> -1680 | E30: =C30 -> -1680 | F30: E7 | G30: 1x IBC klein vol | H30: 800 | I30: =H30 -> 800 | J30: =H30 -> 800 | K30: H7
B31: extra I-profiel 2x4m | C31: =8*18 -> 144 | D31: =C31 -> 144 | E31: =C31 -> 144 | G31: traywash | H31: 50 | I31: =H31 -> 50 | J31: =H31 -> 50
A32: B8 | B32: 1x IBC vol | C32: 1000 | D32: =C32 -> 1000 | E32: =C32 -> 1000 | F32: E8 | K32: H8
A34: C1 | F34: F1 | G34: Brug | H34: 1000 | I34: =H34 -> 1000 | J34: =H34 -> 1000
A36: C2 | B36: vriezer | C36: 150 | D36: =C36 -> 150 | E36: =C36 -> 150 | F36: F2 | G36: shovel (ri G) | H36: 2100 | I36: 2100 | J36: 0
A38: C3 | B38: melktank 3600L | C38: =200+2200 -> 2400 | D38: =200+3600 -> 3800 | E38: =200+3500 -> 3700 | F38: F3 | G38: SIPLO (ri. G) | H38: =300+400 -> 700 | I38: =300+800 -> 1100 | J38: =300 -> 300
A40: C4 | B40: broedcel | C40: 100 | D40: =C40 -> 100 | E40: =C40 -> 100 | F40: F4 | G40: SIPLO (ri. G) | H40: =150 -> 150 | I40: =200 -> 200 | J40: =150 -> 150
B41: dekvloer | C41: =3.75*3.75*0.1*C52 -> 3515.625 | D41: =C41 -> 3515.625 | E41: =C41 -> 3515.625
A42: C5 | B42: zuivel | C42: 150 | D42: =C42 -> 150 | E42: =C42 -> 150 | F42: F5
B43: dekvloer | C43: =C41 -> 3515.625 | D43: =D41 -> 3515.625 | E43: =E41 -> 3515.625
A44: C6 | B44: VF-bakbewerking | C44: 30 | D44: =C44 -> 30 | E44: =C44 -> 30 | F44: F6 | G44: grijze kist agrifirm | H44: =200 -> 200 | I44: 250 | J44: 0
G45: zaagsel pallet | H45: =150 -> 150 | I45: =200 -> 200 | J45: =0 -> 0
A46: C7 | B46: pallet kokos 13x4 50L | C46: =8*4*25 -> 800 | D46: =13*4*25 -> 1300 | E46: =2*4*25 -> 200 | F46: F7 | G46: bigbags leeg | H46: 150 | I46: =H46 -> 150 | J46: =H46 -> 150
A48: C8 | F48: F8
B51: OPMERKINGEN / AANVULLENDE GEGEVENS
B52: Dikte zuivelvloer 10cm [kg/m3] | C52: 2500
...

Sheet Verdieping -1
A1: VERDIEPING -1 | C1: Gem | D1: Max | E1: Min | H1: Gem | I1: Max | J1: Min | M1: Gem | N1: Max | O1: Min
A2: A1 | B2: x | F2: D1 | G2: x | K2: G1 | L2: x
A4: A2 | B4: x | F4: D2 | G4: opslag | H4: 100 | I4: =H4 -> 100 | J4: =H4 -> 100 | K4: G2 | L4: opslag | M4: 100 | N4: =M4 -> 100 | O4: =M4 -> 100
A6: A3 | B6: x | F6: D3 | G6: opslag | H6: 100 | I6: =H6 -> 100 | J6: =H6 -> 100 | K6: G3 | L6: opslag | M6: 400 | N6: =M6 -> 400 | O6: =M6 -> 400
A8: A4 | B8: x | F8: D4 | K8: G4 | L8: kaasstelling half | M8: 250 | N8: =M8 -> 250 | O8: =M8 -> 250
A10: A5 | B10: x | F10: D5 | G10: kaasstelling half | H10: =250 -> 250 | I10: =H10 -> 250 | J10: =H10 -> 250 | K10: G5 | L10: kaasstelling vol | M10: 500 | N10: =M10 -> 500 | O10: =M10 -> 500
A12: A6 | B12: x | F12: D6 | G12: VF | H12: 600 | I12: =H12 -> 600 | J12: =H12 -> 600 | K12: G6 | L12: VF lift | M12: 150 | N12: =M12 -> 150 | O12: =M12 -> 150
G13: EPS vloer | H13: =3.75*3.75*0.1*25 -> 35.15625 | I13: =H13 -> 35.15625 | J13: =H13 -> 35.15625 | L13: EPS vloer | M13: =3.75*3.75*0.1*25 -> 35.15625 | N13: =M13 -> 35.15625 | O13: =M13 -> 35.15625
A14: A7 | B14: x | F14: D7 | G14: EPS vloer | H14: =3.75*3.75*0.1*25 -> 35.15625 | I14: =H14 -> 35.15625 | J14: =H14 -> 35.15625 | K14: G7 | L14: watertank VF d1,5 x1,8 m | M14: =N14*0.6 -> 1908.5175 | N14: =(1.5*1.5*PI()/4)*1.8*1000 -> 3180.8626 | O14: =N14*0.3 -> 954.25877
L15: EPS vloer | M15: =3.75*3.75*0.1*25 -> 35.15625 | N15: =M15 -> 35.15625 | O15: =M15 -> 35.15625
A16: A8 | B16: x | F16: D8 | G16: x | K16: G8 | L16: x
A18: B1 | B18: x | F18: E1 | G18: x | K18: H1 | L18: x
A20: B2 | B20: 2x stalen kast zwaar | C20: 150 | D20: =C20 -> 150 | E20: =C20 -> 150 | F20: E2 | G20: werkbank | H20: 50 | I20: =H20 -> 50 | J20: =H20 -> 50 | K20: H2 | L20: x
A22: B3 | B22: 3x IBC vol | C22: 3000 | D22: =C22 -> 3000 | E22: =C22 -> 3000 | F22: E3 | G22: opslag | H22: 250 | I22: =H22 -> 250 | J22: =H22 -> 250 | K22: H3 | L22: x
B23: stalen trap | C23: 250 | D23: =C23 -> 250 | E23: =C23 -> 250
A24: B4 | B24: 3x IBC vol | C24: 3000 | D24: =C24 -> 3000 | E24: =C24 -> 3000 | F24: E4 | K24: H4 | L24: x
B25: opslag | C25: 200 | D25: =C25 -> 200 | E25: =C25 -> 200
A26: B5 | B26: 5x kaasplank | C26: 400 | D26: =C26 -> 400 | E26: =C26 -> 400 | F26: E5 | G26: kaasstelling vol | H26: 500 | I26: =H26 -> 500 | J26: =H26 -> 500 | K26: H5 | L26: x
A28: B6 | B28: VF lift | C28: =250 -> 250 | D28: =C28 -> 250 | E28: =C28 -> 250 | F28: E6 | G28: VF | H28: 600 | I28: =H28 -> 600 | J28: =H28 -> 600 | K28: H6 | L28: x
B29: EPS vloer | C29: =3.75*3.75*0.1*25 -> 35.15625 | D29: =C29 -> 35.15625 | E29: =C29 -> 35.15625 | G29: EPS vloer | H29: =3.75*3.75*0.1*25 -> 35.15625 | I29: =H29 -> 35.15625 | J29: =H29 -> 35.15625
A30: B7 | B30: houten trap + EPS vloer | C30: =100+C29 -> 135.15625 | D30: =C30 -> 135.15625 | E30: =C30 -> 135.15625 | F30: E7 | G30: EPS vloer | H30: =3.75*3.75*0.1*25 -> 35.15625 | I30: =H30 -> 35.15625 | J30: =H30 -> 35.15625 | K30: H7 | L30: x
B31: 3,4x IBC vol | C31: 3400 | D31: =C31 -> 3400 | E31: =C31 -> 3400
A32: B8 | B32: x | F32: E8 | G32: x | K32: H8 | L32: x
A34: C1 | B34: x | F34: F1 | G34: x
A36: C2 | B36: 2x WC | C36: 20 | D36: =C36 -> 20 | E36: =C36 -> 20 | F36: F2 | G36: vuilwatertank 80x120x250 cm | H36: =0.7*I36 -> 1680 | I36: =0.8*1.2*2.5*1000 -> 2400 | J36: =0.2*I36 -> 480
A38: C3 | B38: werkbank | C38: 150 | D38: =C38 -> 150 | E38: =D38 -> 150 | F38: F3 | G38: opslag | H38: 250 | I38: =H38 -> 250 | J38: =H38 -> 250
A40: C4 | B40: 3x kaasplank | C40: 220 | D40: =C40 -> 220 | E40: =C40 -> 220 | F40: F4
A42: C5 | B42: 4x kaasplank | C42: 350 | D42: =C42 -> 350 | E42: =C42 -> 350 | F42: F5 | G42: kaasstelling bijna leeg | H42: 100 | I42: =H42 -> 100 | J42: =H42 -> 100
A44: C6 | B44: VF | C44: 600 | D44: =C44 -> 600 | E44: =C44 -> 600 | F44: F6 | G44: VF | H44: 600 | I44: =H44 -> 600 | J44: =H44 -> 600
B45: EPS vloer | C45: =3.75*3.75*0.1*25 -> 35.15625 | D45: =C45 -> 35.15625 | E45: =C45 -> 35.15625 | G45: EPS vloer | H45: =3.75*3.75*0.1*25 -> 35.15625 | I45: =H45 -> 35.15625 | J45: =H45 -> 35.15625
A46: C7 | B46: EPS vloer | C46: =3.75*3.75*0.1*25 -> 35.15625 | D46: =C46 -> 35.15625 | E46: =C46 -> 35.15625 | F46: F7 | G46: LBK | H46: 200 | I46: =H46 -> 200 | J46: =H46 -> 200
G47: EPS vloer | H47: =3.75*3.75*0.1*25 -> 35.15625 | I47: =H47 -> 35.15625 | J47: =H47 -> 35.15625
A48: C8 | B48: x | F48: F8 | G48: x
B51: OPMERKINGEN / AANVULLENDE GEGEVENS
B52: B6 t/m G6 + B7 t/m G7 EPS vloer

Sheet Belastingsverdeling
A1: Belastingsverdeling (Eenheid: kilogram)
A2: VERDIEPING 1 | L2: VERDIEPING 0 | W2: VERDIEPING -1
A3: 9 | L3: 9 | W3: 9
A4: 8 | B4: =SUM('Verdieping 1'!C16:C17) -> 1000 | C4: =SUM('Verdieping 1'!C32:C33) -> -197.95961 | D4: =SUM('Verdieping 1'!C48:C49) -> 0 | E4: =SUM('Verdieping 1'!H16:H17) -> 0 | F4: =SUM('Verdieping 1'!H32:H33) -> 0 | G4: =SUM('Verdieping 1'!H48:H49) -> 0 | H4: =SUM('Verdieping 1'!M16:M17) -> -197.95961 | I4: =SUM('Verdieping 1'!M32:M33) -> 129.375 | L4: 8 | M4: =SUM('Verdieping 0'!C16:C17) -> 0 | N4: =SUM('Verdieping 0'!C32:C33) -> 1000 | O4: =SUM('Verdieping 0'!C48:C49) -> 0 | P4: =SUM('Verdieping 0'!H16:H17) -> 0 | Q4: =SUM('Verdieping 0'!H32:H33) -> 0 | R4: =SUM('Verdieping 0'!H48:H49) -> 0 | S4: =SUM('Verdieping 0'!M16:M17) -> 0 | T4: =SUM('Verdieping 0'!M32:M33) -> 0 | W4: 8 | X4: =SUM('Verdieping -1'!C16:C17) -> 0 | Y4: =SUM('Verdieping -1'!C32:C33) -> 0 | Z4: =SUM('Verdieping -1'!C48:C49) -> 0 | AA4: =SUM('Verdieping -1'!H16:H17) -> 0 | AB4: =SUM('Verdieping -1'!H32:H33) -> 0 | AC4: =SUM('Verdieping -1'!H48:H49) -> 0 | AD4: =SUM('Verdieping -1'!M16:M17) -> 0 | AE4: =SUM('Verdieping -1'!M32:M33) -> 0
A5: 7 | B5: =SUM('Verdieping 1'!C14:C15) -> 0 | C5: =SUM('Verdieping 1'!C30:C31) -> 0 | D5: =SUM('Verdieping 1'!C46:C47) -> 0 | E5: =SUM('Verdieping 1'!H14:H15) -> 0 | F5: =SUM('Verdieping 1'!H30:H31) -> 0 | G5: =SUM('Verdieping 1'!H46:H47) -> 0 | H5: =SUM('Verdieping 1'!M14:M15) -> 637.5 | I5: =SUM('Verdieping 1'!M30:M31) -> 129.375 | L5: 7 | M5: =SUM('Verdieping 0'!C14:C15) -> 0 | N5: =SUM('Verdieping 0'!C30:C31) -> -1536 | O5: =SUM('Verdieping 0'!C46:C47) -> 800 | P5: =SUM('Verdieping 0'!H14:H15) -> 0 | Q5: =SUM('Verdieping 0'!H30:H31) -> 850 | R5: =SUM('Verdieping 0'!H46:H47) -> 150 | S5: =SUM('Verdieping 0'!M14:M15) -> 850 | T5: =SUM('Verdieping 0'!M30:M31) -> 0 | W5: 7 | X5: =SUM('Verdieping -1'!C14:C15) -> 0 | Y5: =SUM('Verdieping -1'!C30:C31) -> 3535.1562 | Z5: =SUM('Verdieping -1'!C46:C47) -> 35.15625 | AA5: =SUM('Verdieping -1'!H14:H15) -> 35.15625 | AB5: =SUM('Verdieping -1'!H30:H31) -> 35.15625 | AC5: =SUM('Verdieping -1'!H46:H47) -> 235.15625 | AD5: =SUM('Verdieping -1'!M14:M15) -> 1943.6738 | AE5: =SUM('Verdieping -1'!M30:M31) -> 0
A6: 6 | B6: =SUM('Verdieping 1'!C12:C13) -> 0 | C6: =SUM('Verdieping 1'!C28:C29) -> 0 | D6: =SUM('Verdieping 1'!C44:C45) -> 0 | E6: =SUM('Verdieping 1'!H12:H13) -> 0 | F6: =SUM('Verdieping 1'!H28:H29) -> 0 | G6: =SUM('Verdieping 1'!H44:H45) -> 0 | H6: =SUM('Verdieping 1'!M12:M13) -> 512.5 | I6: =SUM('Verdieping 1'!M28:M29) -> 129.375 | L6: 6 | M6: =SUM('Verdieping 0'!C12:C13) -> 0 | N6: =SUM('Verdieping 0'!C28:C29) -> -3750 | O6: =SUM('Verdieping 0'!C44:C45) -> 30 | P6: =SUM('Verdieping 0'!H12:H13) -> 250 | Q6: =SUM('Verdieping 0'!H28:H29) -> 913.26988 | R6: =SUM('Verdieping 0'!H44:H45) -> 350 | S6: =SUM('Verdieping 0'!M12:M13) -> 775 | T6: =SUM('Verdieping 0'!M28:M29) -> 30 | W6: 6 | X6: =SUM('Verdieping -1'!C12:C13) -> 0 | Y6: =SUM('Verdieping -1'!C28:C29) -> 285.15625 | Z6: =SUM('Verdieping -1'!C44:C45) -> 635.15625 | AA6: =SUM('Verdieping -1'!H12:H13) -> 635.15625 | AB6: =SUM('Verdieping -1'!H28:H29) -> 635.15625 | AC6: =SUM('Verdieping -1'!H44:H45) -> 635.15625 | AD6: =SUM('Verdieping -1'!M12:M13) -> 185.15625 | AE6: =SUM('Verdieping -1'!M28:M29) -> 0
A7: 5 | B7: =SUM('Verdieping 1'!C10:C11) -> 0 | C7: =SUM('Verdieping 1'!C26:C27) -> 0 | D7: =SUM('Verdieping 1'!C42:C43) -> 0 | E7: =SUM('Verdieping 1'!H10:H11) -> 0 | F7: =SUM('Verdieping 1'!H26:H27) -> 0 | G7: =SUM('Verdieping 1'!H42:H43) -> 0 | H7: =SUM('Verdieping 1'!M10:M11) -> 50 | I7: =SUM('Verdieping 1'!M26:M27) -> 254.77322 | L7: 5 | M7: =SUM('Verdieping 0'!C10:C11) -> 0 | N7: =SUM('Verdieping 0'!C26:C27) -> 200 | O7: =SUM('Verdieping 0'!C42:C43) -> 3665.625 | P7: =SUM('Verdieping 0'!H10:H11) -> 3715.625 | Q7: =SUM('Verdieping 0'!H26:H27) -> 3815.625 | R7: =SUM('Verdieping 0'!H42:H43) -> 0 | S7: =SUM('Verdieping 0'!M10:M11) -> 3700 | T7: =SUM('Verdieping 0'!M26:M27) -> 75 | W7: 5 | X7: =SUM('Verdieping -1'!C10:C11) -> 0 | Y7: =SUM('Verdieping -1'!C26:C27) -> 400 | Z7: =SUM('Verdieping -1'!C42:C43) -> 350 | AA7: =SUM('Verdieping -1'!H10:H11) -> 250 | AB7: =SUM('Verdieping -1'!H26:H27) -> 500 | AC7: =SUM('Verdieping -1'!H42:H43) -> 100 | AD7: =SUM('Verdieping -1'!M10:M11) -> 500 | AE7: =SUM('Verdieping -1'!M26:M27) -> 0
A8: 4 | B8: =SUM('Verdieping 1'!C8:C9) -> 0 | C8: =SUM('Verdieping 1'!C24:C25) -> 0 | D8: =SUM('Verdieping 1'!C40:C41) -> 0 | E8: =SUM('Verdieping 1'!H8:H9) -> 0 | F8: =SUM('Verdieping 1'!H24:H25) -> 0 | G8: =SUM('Verdieping 1'!H40:H41) -> 18600 | H8: =SUM('Verdieping 1'!M8:M9) -> 50 | I8: =SUM('Verdieping 1'!M24:M25) -> 204.375 | L8: 4 | M8: =SUM('Verdieping 0'!C8:C9) -> 0 | N8: =SUM('Verdieping 0'!C24:C25) -> -1540 | O8: =SUM('Verdieping 0'!C40:C41) -> 3615.625 | P8: =SUM('Verdieping 0'!H8:H9) -> 3755.625 | Q8: =SUM('Verdieping 0'!H24:H25) -> 3875.625 | R8: =SUM('Verdieping 0'!H40:H41) -> 150 | S8: =SUM('Verdieping 0'!M8:M9) -> 1200 | T8: =SUM('Verdieping 0'!M24:M25) -> 0 | W8: 4 | X8: =SUM('Verdieping -1'!C8:C9) -> 0 | Y8: =SUM('Verdieping -1'!C24:C25) -> 3200 | Z8: =SUM('Verdieping -1'!C40:C41) -> 220 | AA8: =SUM('Verdieping -1'!H8:H9) -> 0 | AB8: =SUM('Verdieping -1'!H24:H25) -> 0 | AC8: =SUM('Verdieping -1'!H40:H41) -> 0 | AD8: =SUM('Verdieping -1'!M8:M9) -> 250 | AE8: =SUM('Verdieping -1'!M24:M25) -> 0
A9: 3 | B9: =SUM('Verdieping 1'!C6:C7) -> 0 | C9: =SUM('Verdieping 1'!C22:C23) -> 0 | D9: =SUM('Verdieping 1'!C38:C39) -> 0 | E9: =SUM('Verdieping 1'!H6:H7) -> 0 | F9: =SUM('Verdieping 1'!H22:H23) -> 0 | G9: =SUM('Verdieping 1'!H38:H39) -> 0 | H9: =SUM('Verdieping 1'!M6:M7) -> 562.5 | I9: =SUM('Verdieping 1'!M22:M23) -> 129.375 | L9: 3 | M9: =SUM('Verdieping 0'!C6:C7) -> 0 | N9: =SUM('Verdieping 0'!C22:C23) -> -1540 | O9: =SUM('Verdieping 0'!C38:C39) -> 2400 | P9: =SUM('Verdieping 0'!H6:H7) -> 110 | Q9: =SUM('Verdieping 0'!H22:H23) -> 2000 | R9: =SUM('Verdieping 0'!H38:H39) -> 700 | S9: =SUM('Verdieping 0'!M6:M7) -> 1200 | T9: =SUM('Verdieping 0'!M22:M23) -> 0 | W9: 3 | X9: =SUM('Verdieping -1'!C6:C7) -> 0 | Y9: =SUM('Verdieping -1'!C22:C23) -> 3250 | Z9: =SUM('Verdieping -1'!C38:C39) -> 150 | AA9: =SUM('Verdieping -1'!H6:H7) -> 100 | AB9: =SUM('Verdieping -1'!H22:H23) -> 250 | AC9: =SUM('Verdieping -1'!H38:H39) -> 250 | AD9: =SUM('Verdieping -1'!M6:M7) -> 400 | AE9: =SUM('Verdieping -1'!M22:M23) -> 0
A10: 2 | B10: =SUM('Verdieping 1'!C4:C5) -> 100 | C10: =SUM('Verdieping 1'!C20:C21) -> 0 | D10: =SUM('Verdieping 1'!C36:C37) -> 0 | E10: =SUM('Verdieping 1'!H4:H5) -> 0 | F10: =SUM('Verdieping 1'!H20:H21) -> 0 | G10: =SUM('Verdieping 1'!H36:H37) -> 0 | H10: =SUM('Verdieping 1'!M4:M5) -> 700 | I10: =SUM('Verdieping 1'!M20:M21) -> 129.375 | L10: 2 | M10: =SUM('Verdieping 0'!C4:C5) -> 0 | N10: =SUM('Verdieping 0'!C20:C21) -> 200 | O10: =SUM('Verdieping 0'!C36:C37) -> 150 | P10: =SUM('Verdieping 0'!H4:H5) -> 0 | Q10: =SUM('Verdieping 0'!H20:H21) -> 260 | R10: =SUM('Verdieping 0'!H36:H37) -> 2100 | S10: =SUM('Verdieping 0'!M4:M5) -> 400 | T10: =SUM('Verdieping 0'!M20:M21) -> 0 | W10: 2 | X10: =SUM('Verdieping -1'!C4:C5) -> 0 | Y10: =SUM('Verdieping -1'!C20:C21) -> 150 | Z10: =SUM('Verdieping -1'!C36:C37) -> 20 | AA10: =SUM('Verdieping -1'!H4:H5) -> 100 | AB10: =SUM('Verdieping -1'!H20:H21) -> 50 | AC10: =SUM('Verdieping -1'!H36:H37) -> 1680 | AD10: =SUM('Verdieping -1'!M4:M5) -> 100 | AE10: =SUM('Verdieping -1'!M20:M21) -> 0
A11: 1 | B11: =SUM('Verdieping 1'!C2:C3) -> 1100 | C11: =SUM('Verdieping 1'!C18:C19) -> 0 | D11: =SUM('Verdieping 1'!C34:C35) -> 1300 | E11: =SUM('Verdieping 1'!H2:H3) -> 0 | F11: =SUM('Verdieping 1'!H18:H19) -> 0 | G11: =SUM('Verdieping 1'!H34:H35) -> 0 | H11: =SUM('Verdieping 1'!M2:M3) -> 0 | I11: =SUM('Verdieping 1'!M18:M19) -> 129.375 | L11: 1 | M11: =SUM('Verdieping 0'!C2:C3) -> 0 | N11: =SUM('Verdieping 0'!C18:C19) -> 0 | O11: =SUM('Verdieping 0'!C34:C35) -> 0 | P11: =SUM('Verdieping 0'!H2:H3) -> 0 | Q11: =SUM('Verdieping 0'!H18:H19) -> 0 | R11: =SUM('Verdieping 0'!H34:H35) -> 1000 | S11: =SUM('Verdieping 0'!M2:M3) -> 130 | T11: =SUM('Verdieping 0'!M18:M19) -> 0 | W11: 1 | X11: =SUM('Verdieping -1'!C2:C3) -> 0 | Y11: =SUM('Verdieping -1'!C18:C19) -> 0 | Z11: =SUM('Verdieping -1'!C34:C35) -> 0 | AA11: =SUM('Verdieping -1'!H2:H3) -> 0 | AB11: =SUM('Verdieping -1'!H18:H19) -> 0 | AC11: =SUM('Verdieping -1'!H34:H35) -> 0 | AD11: =SUM('Verdieping -1'!M2:M3) -> 0 | AE11: =SUM('Verdieping -1'!M18:M19) -> 0
B12: A | C12: B | D12: C | E12: D | F12: E | G12: F | H12: G | I12: H | J12: I | M12: A | N12: B | O12: C | P12: D | Q12: E | R12: F | S12: G | T12: H | U12: I | X12: A | Y12: B | Z12: C | AA12: D | AB12: E | AC12: F | AD12: G | AE12: H | AF12: I

Sheet Moment verdeling hor. as
A1: Moment verdeling horizontale as (Eenheid: kg*m)
A2: VERDIEPING 1 | L2: VERDIEPING 0 | W2: VERDIEPING -1 | AH2: TOTAAL
A3: 9 | L3: 9 | W3: 9 | AH3: 9
A4: 8 | B4: =SUM('Verdieping 1'!C16:C17)*3.5*3.75 -> 13125 | C4: =SUM('Verdieping 1'!C32:C33)*3.5*3.75 -> -2598.2198 | D4: =SUM('Verdieping 1'!C48:C49)*3.5*3.75 -> 0 | E4: =SUM('Verdieping 1'!H16:H17)*3.5*3.75 -> 0 | F4: =SUM('Verdieping 1'!H32:H33)*3.5*3.75 -> 0 | G4: =SUM('Verdieping 1'!H48:H49)*3.5*3.75 -> 0 | H4: =SUM('Verdieping 1'!M16:M17)*3.5*3.75 -> -2598.2198 | I4: =SUM('Verdieping 1'!M32:M33)*3.5*3.75 -> 1698.0469 | K4: =SUM(B4:I7) -> 20998.057 | L4: 8 | M4: =SUM('Verdieping 0'!C16:C17)*3.5*3.75 -> 0 | N4: =SUM('Verdieping 0'!C32:C33)*3.5*3.75 -> 13125 | O4: =SUM('Verdieping 0'!C48:C49)*3.5*3.75 -> 0 | P4: =SUM('Verdieping 0'!H16:H17)*3.5*3.75 -> 0 | Q4: =SUM('Verdieping 0'!H32:H33)*3.5*3.75 -> 0 | R4: =SUM('Verdieping 0'!H48:H49)*3.5*3.75 -> 0 | S4: =SUM('Verdieping 0'!M16:M17)*3.5*3.75 -> 0 | T4: =SUM('Verdieping 0'!M32:M33)*3.5*3.75 -> 0 | V4: =SUM(M4:T7) -> 44131.284 | W4: 8 | X4: =SUM('Verdieping -1'!C16:C17)*3.5*3.75 -> 0 | Y4: =SUM('Verdieping -1'!C32:C33)*3.5*3.75 -> 0 | Z4: =SUM('Verdieping -1'!C48:C49)*3.5*3.75 -> 0 | AA4: =SUM('Verdieping -1'!H16:H17)*3.5*3.75 -> 0 | AB4: =SUM('Verdieping -1'!H32:H33)*3.5*3.75 -> 0 | AC4: =SUM('Verdieping -1'!H48:H49)*3.5*3.75 -> 0 | AD4: =SUM('Verdieping -1'!M16:M17)*3.5*3.75 -> 0 | AE4: =SUM('Verdieping -1'!M32:M33)*3.5*3.75 -> 0 | AG4: =SUM(X4:AE7) -> 75431.414 | AH4: 8 | AI4: =SUM(B4,M4,X4) -> 13125 | AJ4: =SUM(C4,N4,Y4) -> 10526.78 | AK4: =SUM(D4,O4,Z4) -> 0 | AL4: =SUM(E4,P4,AA4) -> 0 | AM4: =SUM(F4,Q4,AB4) -> 0 | AN4: =SUM(G4,R4,AC4) -> 0 | AO4: =SUM(H4,S4,AD4) -> -2598.2198 | AP4: =SUM(I4,T4,AE4) -> 1698.0469
A5: 7 | B5: =SUM('Verdieping 1'!C14:C15)*2.5*3.75 -> 0 | C5: =SUM('Verdieping 1'!C30:C31)*2.5*3.75 -> 0 | D5: =SUM('Verdieping 1'!C46:C47)*2.5*3.75 -> 0 | E5: =SUM('Verdieping 1'!H14:H15)*2.5*3.75 -> 0 | F5: =SUM('Verdieping 1'!H30:H31)*2.5*3.75 -> 0 | G5: =SUM('Verdieping 1'!H46:H47)*2.5*3.75 -> 0 | H5: =SUM('Verdieping 1'!M14:M15)*2.5*3.75 -> 5976.5625 | I5: =SUM('Verdieping 1'!M30:M31)*2.5*3.75 -> 1212.8906 | L5: 7 | M5: =SUM('Verdieping 0'!C14:C15)*2.5*3.75 -> 0 | N5: =SUM('Verdieping 0'!C30:C31)*2.5*3.75 -> -14400 | O5: =SUM('Verdieping 0'!C46:C47)*2.5*3.75 -> 7500 | P5: =SUM('Verdieping 0'!H14:H15)*2.5*3.75 -> 0 | Q5: =SUM('Verdieping 0'!H30:H31)*2.5*3.75 -> 7968.75 | R5: =SUM('Verdieping 0'!H46:H47)*2.5*3.75 -> 1406.25 | S5: =SUM('Verdieping 0'!M14:M15)*2.5*3.75 -> 7968.75 | T5: =SUM('Verdieping 0'!M30:M31)*2.5*3.75 -> 0 | W5: 7 | X5: =SUM('Verdieping -1'!C14:C15)*2.5*3.75 -> 0 | Y5: =SUM('Verdieping -1'!C30:C31)*2.5*3.75 -> 33142.09 | Z5: =SUM('Verdieping -1'!C46:C47)*2.5*3.75 -> 329.58984 | AA5: =SUM('Verdieping -1'!H14:H15)*2.5*3.75 -> 329.58984 | AB5: =SUM('Verdieping -1'!H30:H31)*2.5*3.75 -> 329.58984 | AC5: =SUM('Verdieping -1'!H46:H47)*2.5*3.75 -> 2204.5898 | AD5: =SUM('Verdieping -1'!M14:M15)*2.5*3.75 -> 18221.942 | AE5: =SUM('Verdieping -1'!M30:M31)*2.5*3.75 -> 0 | AH5: 7 | AI5: =SUM(B5,M5,X5) -> 0 | AJ5: =SUM(C5,N5,Y5) -> 18742.09 | AK5: =SUM(D5,O5,Z5) -> 7829.5898 | AL5: =SUM(E5,P5,AA5) -> 329.58984 | AM5: =SUM(F5,Q5,AB5) -> 8298.3398 | AN5: =SUM(G5,R5,AC5) -> 3610.8398 | AO5: =SUM(H5,S5,AD5) -> 32167.254 | AP5: =SUM(I5,T5,AE5) -> 1212.8906
A6: 6 | B6: =SUM('Verdieping 1'!C12:C13)*1.5*3.75 -> 0 | C6: =SUM('Verdieping 1'!C28:C29)*1.5*3.75 -> 0 | D6: =SUM('Verdieping 1'!C44:C45)*1.5*3.75 -> 0 | E6: =SUM('Verdieping 1'!H12:H13)*1.5*3.75 -> 0 | F6: =SUM('Verdieping 1'!H28:H29)*1.5*3.75 -> 0 | G6: =SUM('Verdieping 1'!H44:H45)*1.5*3.75 -> 0 | H6: =SUM('Verdieping 1'!M12:M13)*1.5*3.75 -> 2882.8125 | I6: =SUM('Verdieping 1'!M28:M29)*1.5*3.75 -> 727.73438 | L6: 6 | M6: =SUM('Verdieping 0'!C12:C13)*1.5*3.75 -> 0 | N6: =SUM('Verdieping 0'!C28:C29)*1.5*3.75 -> -21093.75 | O6: =SUM('Verdieping 0'!C44:C45)*1.5*3.75 -> 168.75 | P6: =SUM('Verdieping 0'!H12:H13)*1.5*3.75 -> 1406.25 | Q6: =SUM('Verdieping 0'!H28:H29)*1.5*3.75 -> 5137.1431 | R6: =SUM('Verdieping 0'!H44:H45)*1.5*3.75 -> 1968.75 | S6: =SUM('Verdieping 0'!M12:M13)*1.5*3.75 -> 4359.375 | T6: =SUM('Verdieping 0'!M28:M29)*1.5*3.75 -> 168.75 | W6: 6 | X6: =SUM('Verdieping -1'!C12:C13)*1.5*3.75 -> 0 | Y6: =SUM('Verdieping -1'!C28:C29)*1.5*3.75 -> 1604.0039 | Z6: =SUM('Verdieping -1'!C44:C45)*1.5*3.75 -> 3572.7539 | AA6: =SUM('Verdieping -1'!H12:H13)*1.5*3.75 -> 3572.7539 | AB6: =SUM('Verdieping -1'!H28:H29)*1.5*3.75 -> 3572.7539 | AC6: =SUM('Verdieping -1'!H44:H45)*1.5*3.75 -> 3572.7539 | AD6: =SUM('Verdieping -1'!M12:M13)*1.5*3.75 -> 1041.5039 | AE6: =SUM('Verdieping -1'!M28:M29)*1.5*3.75 -> 0 | AH6: 6 | AI6: =SUM(B6,M6,X6) -> 0 | AJ6: =SUM(C6,N6,Y6) -> -19489.746 | AK6: =SUM(D6,O6,Z6) -> 3741.5039 | AL6: =SUM(E6,P6,AA6) -> 4979.0039 | AM6: =SUM(F6,Q6,AB6) -> 8709.897 | AN6: =SUM(G6,R6,AC6) -> 5541.5039 | AO6: =SUM(H6,S6,AD6) -> 8283.6914 | AP6: =SUM(I6,T6,AE6) -> 896.48438
A7: 5 | B7: =SUM('Verdieping 1'!C10:C11)*0.5*3.75 -> 0 | C7: =SUM('Verdieping 1'!C26:C27)*0.5*3.75 -> 0 | D7: =SUM('Verdieping 1'!C42:C43)*0.5*3.75 -> 0 | E7: =SUM('Verdieping 1'!H10:H11)*0.5*3.75 -> 0 | F7: =SUM('Verdieping 1'!H26:H27)*0.5*3.75 -> 0 | G7: =SUM('Verdieping 1'!H42:H43)*0.5*3.75 -> 0 | H7: =SUM('Verdieping 1'!M10:M11)*0.5*3.75 -> 93.75 | I7: =SUM('Verdieping 1'!M26:M27)*0.5*3.75 -> 477.69979 | L7: 5 | M7: =SUM('Verdieping 0'!C10:C11)*0.5*3.75 -> 0 | N7: =SUM('Verdieping 0'!C26:C27)*0.5*3.75 -> 375 | O7: =SUM('Verdieping 0'!C42:C43)*0.5*3.75 -> 6873.0469 | P7: =SUM('Verdieping 0'!H10:H11)*0.5*3.75 -> 6966.7969 | Q7: =SUM('Verdieping 0'!H26:H27)*0.5*3.75 -> 7154.2969 | R7: =SUM('Verdieping 0'!H42:H43)*0.5*3.75 -> 0 | S7: =SUM('Verdieping 0'!M10:M11)*0.5*3.75 -> 6937.5 | T7: =SUM('Verdieping 0'!M26:M27)*0.5*3.75 -> 140.625 | W7: 5 | X7: =SUM('Verdieping -1'!C10:C11)*0.5*3.75 -> 0 | Y7: =SUM('Verdieping -1'!C26:C27)*0.5*3.75 -> 750 | Z7: =SUM('Verdieping -1'!C42:C43)*0.5*3.75 -> 656.25 | AA7: =SUM('Verdieping -1'!H10:H11)*0.5*3.75 -> 468.75 | AB7: =SUM('Verdieping -1'!H26:H27)*0.5*3.75 -> 937.5 | AC7: =SUM('Verdieping -1'!H42:H43)*0.5*3.75 -> 187.5 | AD7: =SUM('Verdieping -1'!M10:M11)*0.5*3.75 -> 937.5 | AE7: =SUM('Verdieping -1'!M26:M27)*0.5*3.75 -> 0 | AH7: 5 | AI7: =SUM(B7,M7,X7) -> 0 | AJ7: =SUM(C7,N7,Y7) -> 1125 | AK7: =SUM(D7,O7,Z7) -> 7529.2969 | AL7: =SUM(E7,P7,AA7) -> 7435.5469 | AM7: =SUM(F7,Q7,AB7) -> 8091.7969 | AN7: =SUM(G7,R7,AC7) -> 187.5 | AO7: =SUM(H7,S7,AD7) -> 7968.75 | AP7: =SUM(I7,T7,AE7) -> 618.32479
A8: 4 | B8: =SUM('Verdieping 1'!C8:C9)*0.5*3.75 -> 0 | C8: =SUM('Verdieping 1'!C24:C25)*0.5*3.75 -> 0 | D8: =SUM('Verdieping 1'!C40:C41)*0.5*3.75 -> 0 | E8: =SUM('Verdieping 1'!H8:H9)*0.5*3.75 -> 0 | F8: =SUM('Verdieping 1'!H24:H25)*0.5*3.75 -> 0 | G8: =SUM('Verdieping 1'!H40:H41)*0.5*3.75 -> 34875 | H8: =SUM('Verdieping 1'!M8:M9)*0.5*3.75 -> 93.75 | I8: =SUM('Verdieping 1'!M24:M25)*0.5*3.75 -> 383.20312 | L8: 4 | M8: =SUM('Verdieping 0'!C8:C9)*0.5*3.75 -> 0 | N8: =SUM('Verdieping 0'!C24:C25)*0.5*3.75 -> -2887.5 | O8: =SUM('Verdieping 0'!C40:C41)*0.5*3.75 -> 6779.2969 | P8: =SUM('Verdieping 0'!H8:H9)*0.5*3.75 -> 7041.7969 | Q8: =SUM('Verdieping 0'!H24:H25)*0.5*3.75 -> 7266.7969 | R8: =SUM('Verdieping 0'!H40:H41)*0.5*3.75 -> 281.25 | S8: =SUM('Verdieping 0'!M8:M9)*0.5*3.75 -> 2250 | T8: =SUM('Verdieping 0'!M24:M25)*0.5*3.75 -> 0 | W8: 4 | X8: =SUM('Verdieping -1'!C8:C9)*0.5*3.75 -> 0 | Y8: =SUM('Verdieping -1'!C24:C25)*0.5*3.75 -> 6000 | Z8: =SUM('Verdieping -1'!C40:C41)*0.5*3.75 -> 412.5 | AA8: =SUM('Verdieping -1'!H8:H9)*0.5*3.75 -> 0 | AB8: =SUM('Verdieping -1'!H24:H25)*0.5*3.75 -> 0 | AC8: =SUM('Verdieping -1'!H40:H41)*0.5*3.75 -> 0 | AD8: =SUM('Verdieping -1'!M8:M9)*0.5*3.75 -> 468.75 | AE8: =SUM('Verdieping -1'!M24:M25)*0.5*3.75 -> 0 | AH8: 4 | AI8: =SUM(B8,M8,X8) -> 0 | AJ8: =SUM(C8,N8,Y8) -> 3112.5 | AK8: =SUM(D8,O8,Z8) -> 7191.7969 | AL8: =SUM(E8,P8,AA8) -> 7041.7969 | AM8: =SUM(F8,Q8,AB8) -> 7266.7969 | AN8: =SUM(G8,R8,AC8) -> 35156.25 | AO8: =SUM(H8,S8,AD8) -> 2812.5 | AP8: =SUM(I8,T8,AE8) -> 383.20312
A9: 3 | B9: =SUM('Verdieping 1'!C6:C7)*1.5*3.75 -> 0 | C9: =SUM('Verdieping 1'!C22:C23)*1.5*3.75 -> 0 | D9: =SUM('Verdieping 1'!C38:C39)*1.5*3.75 -> 0 | E9: =SUM('Verdieping 1'!H6:H7)*1.5*3.75 -> 0 | F9: =SUM('Verdieping 1'!H22:H23)*1.5*3.75 -> 0 | G9: =SUM('Verdieping 1'!H38:H39)*1.5*3.75 -> 0 | H9: =SUM('Verdieping 1'!M6:M7)*1.5*3.75 -> 3164.0625 | I9: =SUM('Verdieping 1'!M22:M23)*1.5*3.75 -> 727.73438 | L9: 3 | M9: =SUM('Verdieping 0'!C6:C7)*1.5*3.75 -> 0 | N9: =SUM('Verdieping 0'!C22:C23)*1.5*3.75 -> -8662.5 | O9: =SUM('Verdieping 0'!C38:C39)*1.5*3.75 -> 13500 | P9: =SUM('Verdieping 0'!H6:H7)*1.5*3.75 -> 618.75 | Q9: =SUM('Verdieping 0'!H22:H23)*1.5*3.75 -> 11250 | R9: =SUM('Verdieping 0'!H38:H39)*1.5*3.75 -> 3937.5 | S9: =SUM('Verdieping 0'!M6:M7)*1.5*3.75 -> 6750 | T9: =SUM('Verdieping 0'!M22:M23)*1.5*3.75 -> 0 | W9: 3 | X9: =SUM('Verdieping -1'!C6:C7)*1.5*3.75 -> 0 | Y9: =SUM('Verdieping -1'!C22:C23)*1.5*3.75 -> 18281.25 | Z9: =SUM('Verdieping -1'!C38:C39)*1.5*3.75 -> 843.75 | AA9: =SUM('Verdieping -1'!H6:H7)*1.5*3.75 -> 562.5 | AB9: =SUM('Verdieping -1'!H22:H23)*1.5*3.75 -> 1406.25 | AC9: =SUM('Verdieping -1'!H38:H39)*1.5*3.75 -> 1406.25 | AD9: =SUM('Verdieping -1'!M6:M7)*1.5*3.75 -> 2250 | AE9: =SUM('Verdieping -1'!M22:M23)*1.5*3.75 -> 0 | AH9: 3 | AI9: =SUM(B9,M9,X9) -> 0 | AJ9: =SUM(C9,N9,Y9) -> 9618.75 | AK9: =SUM(D9,O9,Z9) -> 14343.75 | AL9: =SUM(E9,P9,AA9) -> 1181.25 | AM9: =SUM(F9,Q9,AB9) -> 12656.25 | AN9: =SUM(G9,R9,AC9) -> 5343.75 | AO9: =SUM(H9,S9,AD9) -> 12164.062 | AP9: =SUM(I9,T9,AE9) -> 727.73438
A10: 2 | B10: =SUM('Verdieping 1'!C4:C5)*2.5*3.75 -> 937.5 | C10: =SUM('Verdieping 1'!C20:C21)*2.5*3.75 -> 0 | D10: =SUM('Verdieping 1'!C36:C37)*2.5*3.75 -> 0 | E10: =SUM('Verdieping 1'!H4:H5)*2.5*3.75 -> 0 | F10: =SUM('Verdieping 1'!H20:H21)*2.5*3.75 -> 0 | G10: =SUM('Verdieping 1'!H36:H37)*2.5*3.75 -> 0 | H10: =SUM('Verdieping 1'!M4:M5)*2.5*3.75 -> 6562.5 | I10: =SUM('Verdieping 1'!M20:M21)*2.5*3.75 -> 1212.8906 | L10: 2 | M10: =SUM('Verdieping 0'!C4:C5)*2.5*3.75 -> 0 | N10: =SUM('Verdieping 0'!C20:C21)*2.5*3.75 -> 1875 | O10: =SUM('Verdieping 0'!C36:C37)*2.5*3.75 -> 1406.25 | P10: =SUM('Verdieping 0'!H4:H5)*2.5*3.75 -> 0 | Q10: =SUM('Verdieping 0'!H20:H21)*2.5*3.75 -> 2437.5 | R10: =SUM('Verdieping 0'!H36:H37)*2.5*3.75 -> 19687.5 | S10: =SUM('Verdieping 0'!M4:M5)*2.5*3.75 -> 3750 | T10: =SUM('Verdieping 0'!M20:M21)*2.5*3.75 -> 0 | W10: 2 | X10: =SUM('Verdieping -1'!C4:C5)*2.5*3.75 -> 0 | Y10: =SUM('Verdieping -1'!C20:C21)*2.5*3.75 -> 1406.25 | Z10: =SUM('Verdieping -1'!C36:C37)*2.5*3.75 -> 187.5 | AA10: =SUM('Verdieping -1'!H4:H5)*2.5*3.75 -> 937.5 | AB10: =SUM('Verdieping -1'!H20:H21)*2.5*3.75 -> 468.75 | AC10: =SUM('Verdieping -1'!H36:H37)*2.5*3.75 -> 15750 | AD10: =SUM('Verdieping -1'!M4:M5)*2.5*3.75 -> 937.5 | AE10: =SUM('Verdieping -1'!M20:M21)*2.5*3.75 -> 0 | AH10: 2 | AI10: =SUM(B10,M10,X10) -> 937.5 | AJ10: =SUM(C10,N10,Y10) -> 3281.25 | AK10: =SUM(D10,O10,Z10) -> 1593.75 | AL10: =SUM(E10,P10,AA10) -> 937.5 | AM10: =SUM(F10,Q10,AB10) -> 2906.25 | AN10: =SUM(G10,R10,AC10) -> 35437.5 | AO10: =SUM(H10,S10,AD10) -> 11250 | AP10: =SUM(I10,T10,AE10) -> 1212.8906
A11: 1 | B11: =SUM('Verdieping 1'!C2:C3)*3.5*3.75 -> 14437.5 | C11: =SUM('Verdieping 1'!C18:C19)*3.5*3.75 -> 0 | D11: =SUM('Verdieping 1'!C34:C35)*3.5*3.75 -> 17062.5 | E11: =SUM('Verdieping 1'!H2:H3)*3.5*3.75 -> 0 | F11: =SUM('Verdieping 1'!H18:H19)*3.5*3.75 -> 0 | G11: =SUM('Verdieping 1'!H34:H35)*3.5*3.75 -> 0 | H11: =SUM('Verdieping 1'!M2:M3)*3.5*3.75 -> 0 | I11: =SUM('Verdieping 1'!M18:M19)*3.5*3.75 -> 1698.0469 | K11: =SUM(B8:I11) -> 81154.688 | L11: 1 | M11: =SUM('Verdieping 0'!C2:C3)*3.5*3.75 -> 0 | N11: =SUM('Verdieping 0'!C18:C19)*3.5*3.75 -> 0 | O11: =SUM('Verdieping 0'!C34:C35)*3.5*3.75 -> 0 | P11: =SUM('Verdieping 0'!H2:H3)*3.5*3.75 -> 0 | Q11: =SUM('Verdieping 0'!H18:H19)*3.5*3.75 -> 0 | R11: =SUM('Verdieping 0'!H34:H35)*3.5*3.75 -> 13125 | S11: =SUM('Verdieping 0'!M2:M3)*3.5*3.75 -> 1706.25 | T11: =SUM('Verdieping 0'!M18:M19)*3.5*3.75 -> 0 | V11: =SUM(M8:T11) -> 92112.891 | W11: 1 | X11: =SUM('Verdieping -1'!C2:C3)*3.5*3.75 -> 0 | Y11: =SUM('Verdieping -1'!C18:C19)*3.5*3.75 -> 0 | Z11: =SUM('Verdieping -1'!C34:C35)*3.5*3.75 -> 0 | AA11: =SUM('Verdieping -1'!H2:H3)*3.5*3.75 -> 0 | AB11: =SUM('Verdieping -1'!H18:H19)*3.5*3.75 -> 0 | AC11: =SUM('Verdieping -1'!H34:H35)*3.5*3.75 -> 0 | AD11: =SUM('Verdieping -1'!M2:M3)*3.5*3.75 -> 0 | AE11: =SUM('Verdieping -1'!M18:M19)*3.5*3.75 -> 0 | AG11: =SUM(X8:AE11) -> 51318.75 | AH11: 1 | AI11: =SUM(B11,M11,X11) -> 14437.5 | AJ11: =SUM(C11,N11,Y11) -> 0 | AK11: =SUM(D11,O11,Z11) -> 17062.5 | AL11: =SUM(E11,P11,AA11) -> 0 | AM11: =SUM(F11,Q11,AB11) -> 0 | AN11: =SUM(G11,R11,AC11) -> 13125 | AO11: =SUM(H11,S11,AD11) -> 1706.25 | AP11: =SUM(I11,T11,AE11) -> 1698.0469
B12: A | C12: B | D12: C | E12: D | F12: E | G12: F | H12: G | I12: H | J12: I | M12: A | N12: B | O12: C | P12: D | Q12: E | R12: F | S12: G | T12: H | U12: I | X12: A | Y12: B | Z12: C | AA12: D | AB12: E | AC12: F | AD12: G | AE12: H | AF12: I | AI12: A | AJ12: B | AK12: C | AL12: D | AM12: E | AN12: F | AO12: G | AP12: H | AQ12: I | AX12: 𝑉 = 𝑔 ⋅ 𝜌/(𝑀⋅ 𝑠)
AR13: N*m | AT13: Moment abs (Nm) | AU13: arm tot middelpunt van tank(m) | AV13: dichtheidvloeistof (kg/m³) | AW13: zwaartekracht (N) | AX13: volume tank (m³)
AO14: Totaal moment bovenste helft | AP14: =SUM(K4,V4,AG4) -> 140560.76 | AR14: =AP14*AO$21 -> 1378430.1 | AT14: =ABS(AR$16) -> 824009.39 | AU14: 1 | AV14: 997 | AW14: 9.81 | AX14: =AT14/(AW14*AV14*AU14) -> 84.249628
AO15: Totaal moment onderste helft | AP15: =SUM(K11,V11,AG11) -> 224586.33 | AR15: =AP15*AO$21 -> 2202439.5 | AT15: =ABS(AR$16) -> 824009.39 | AU15: =AU14+1 -> 2 | AV15: 997 | AW15: 9.81 | AX15: =AT15/(AW15*AV15*AU15) -> 42.124814
AO16: Totaal moment verschil | AP16: =AP14-AP15 -> -84025.573 | AR16: =AP16*AO$21 -> -824009.39 | AT16: =ABS(AR$16) -> 824009.39 | AU16: =AU15+1 -> 3 | AV16: 997 | AW16: 9.81 | AX16: =AT16/(AW16*AV16*AU16) -> 28.083209
AO17: Pos waarde betekent meer gewicht bovenste helft | AT17: =ABS(AR$16) -> 824009.39 | AU17: =AU16+1 -> 4 | AV17: 997 | AW17: 9.81 | AX17: =AT17/(AW17*AV17*AU17) -> 21.062407
AT18: =ABS(AR$16) -> 824009.39 | AU18: =AU17+1 -> 5 | AV18: 997 | AW18: 9.81 | AX18: =AT18/(AW18*AV18*AU18) -> 16.849926
AT19: =ABS(AR$16) -> 824009.39 | AU19: =AU18+1 -> 6 | AV19: 997 | AW19: 9.81 | AX19: =AT19/(AW19*AV19*AU19) -> 14.041605
AO20: 1 kg*m to 1 N*m | AT20: =ABS(AR$16) -> 824009.39 | AU20: =AU19+1 -> 7 | AV20: 997 | AW20: 9.81 | AX20: =AT20/(AW20*AV20*AU20) -> 12.035661
AO21: 9.80665 | AT21: =ABS(AR$16) -> 824009.39 | AU21: =AU20+1 -> 8 | AV21: 997 | AW21: 9.81 | AX21: =AT21/(AW21*AV21*AU21) -> 10.531204
AT22: =ABS(AR$16) -> 824009.39 | AU22: =AU21+1 -> 9 | AV22: 997 | AW22: 9.81 | AX22: =AT22/(AW22*AV22*AU22) -> 9.3610698
AM23: 𝐹 = 𝜌 ⋅ 𝑉 ⋅ 𝑔 | AO23: 𝑉 = 𝐹/𝑔 ⋅ 𝜌 | AT23: =ABS(AR$16) -> 824009.39 | AU23: =AU22+1 -> 10 | AV23: 997 | AW23: 9.81 | AX23: =AT23/(AW23*AV23*AU23) -> 8.4249628
AM24: Waarin: | AT24: =ABS(AR$16) -> 824009.39 | AU24: =AU23+1 -> 11 | AV24: 997 | AW24: 9.81 | AX24: =AT24/(AW24*AV24*AU24) -> 7.6590571
AM25: F: opwaartse kracht [N] | AT25: =ABS(AR$16) -> 824009.39 | AU25: =AU24+1 -> 12 | AV25: 997 | AW25: 9.81 | AX25: =AT25/(AW25*AV25*AU25) -> 7.0208023
AM26: ρ: dichtheid van de vloeistof [kg/m³] | AT26: =ABS(AR$16) -> 824009.39 | AU26: =AU25+1 -> 13 | AV26: 997 | AW26: 9.81 | AX26: =AT26/(AW26*AV26*AU26) -> 6.4807406
AM27: V: volume van de verplaatste vloeistof [m³] | AT27: =ABS(AR$16) -> 824009.39 | AU27: =AU26+1 -> 14 | AV27: 997 | AW27: 9.81 | AX27: =AT27/(AW27*AV27*AU27) -> 6.0178306
AM28: g: gravitatieversnelling [N] | AT28: =ABS(AR$16) -> 824009.39 | AU28: =AU27+1 -> 15 | AV28: 997 | AW28: 9.81 | AX28: =AT28/(AW28*AV28*AU28) -> 5.6166419
AM30: 𝑀 = 𝐹 ⋅ 𝑠 | AO30: 𝐹 = 𝑀⋅ 𝑠
AM31: Waarin de symbolen de volgende betekenis hebben:
AM32: M = het moment [Nm]
AM33: F = de kracht (het gewicht per raster vak) [N]
AM34: s = de arm [m]

Sheet Moment verdeling vert. as
A1: Moment verdeling verticale as (Eenheid: kg*m)
A2: VERDIEPING 1 | L2: VERDIEPING 0 | W2: VERDIEPING -1 | AH2: TOTAAL
A3: 9 | L3: 9 | W3: 9 | AH3: 9
A4: 8 | B4: =SUM('Verdieping 1'!C16:C17)*3.5*3.75 -> 13125 | C4: =SUM('Verdieping 1'!C32:C33)*2.5*3.75 -> -1855.8713 | D4: =SUM('Verdieping 1'!C48:C49)*1.5*3.75 -> 0 | E4: =SUM('Verdieping 1'!H16:H17)*0.5*3.75 -> 0 | F4: =SUM('Verdieping 1'!H32:H33)*0.5*3.75 -> 0 | G4: =SUM('Verdieping 1'!H48:H49)*1.5*3.75 -> 0 | H4: =SUM('Verdieping 1'!M16:M17)*2.5*3.75 -> -1855.8713 | I4: =SUM('Verdieping 1'!M32:M33)*3.5*3.75 -> 1698.0469 | L4: 8 | M4: =SUM('Verdieping 0'!C16:C17)*3.5*3.75 -> 0 | N4: =SUM('Verdieping 0'!C32:C33)*2.5*3.75 -> 9375 | O4: =SUM('Verdieping 0'!C48:C49)*1.5*3.75 -> 0 | P4: =SUM('Verdieping 0'!H16:H17)*0.5*3.75 -> 0 | Q4: =SUM('Verdieping 0'!H32:H33)*0.5*3.75 -> 0 | R4: =SUM('Verdieping 0'!H48:H49)*1.5*3.75 -> 0 | S4: =SUM('Verdieping 0'!M16:M17)*2.5*3.75 -> 0 | T4: =SUM('Verdieping 0'!M32:M33)*3.5*3.75 -> 0 | W4: 8 | X4: =SUM('Verdieping -1'!C16:C17)*3.5*3.75 -> 0 | Y4: =SUM('Verdieping -1'!C32:C33)*2.5*3.75 -> 0 | Z4: =SUM('Verdieping -1'!C48:C49)*1.5*3.75 -> 0 | AA4: =SUM('Verdieping -1'!H16:H17)*0.5*3.75 -> 0 | AB4: =SUM('Verdieping -1'!H32:H33)*0.5*3.75 -> 0 | AC4: =SUM('Verdieping -1'!H48:H49)*1.5*3.75 -> 0 | AD4: =SUM('Verdieping -1'!M16:M17)*2.5*3.75 -> 0 | AE4: =SUM('Verdieping -1'!M32:M33)*3.5*3.75 -> 0 | AH4: 8 | AI4: =SUM(B4,M4,X4) -> 13125 | AJ4: =SUM(C4,N4,Y4) -> 7519.1287 | AK4: =SUM(D4,O4,Z4) -> 0 | AL4: =SUM(E4,P4,AA4) -> 0 | AM4: =SUM(F4,Q4,AB4) -> 0 | AN4: =SUM(G4,R4,AC4) -> 0 | AO4: =SUM(H4,S4,AD4) -> -1855.8713 | AP4: =SUM(I4,T4,AE4) -> 1698.0469
A5: 7 | B5: =SUM('Verdieping 1'!C14:C15)*3.5*3.75 -> 0 | C5: =SUM('Verdieping 1'!C30:C31)*2.5*3.75 -> 0 | D5: =SUM('Verdieping 1'!C46:C47)*1.5*3.75 -> 0 | E5: =SUM('Verdieping 1'!H14:H15)*0.5*3.75 -> 0 | F5: =SUM('Verdieping 1'!H30:H31)*0.5*3.75 -> 0 | G5: =SUM('Verdieping 1'!H46:H47)*1.5*3.75 -> 0 | H5: =SUM('Verdieping 1'!M14:M15)*2.5*3.75 -> 5976.5625 | I5: =SUM('Verdieping 1'!M30:M31)*3.5*3.75 -> 1698.0469 | L5: 7 | M5: =SUM('Verdieping 0'!C14:C15)*3.5*3.75 -> 0 | N5: =SUM('Verdieping 0'!C30:C31)*2.5*3.75 -> -14400 | O5: =SUM('Verdieping 0'!C46:C47)*1.5*3.75 -> 4500 | P5: =SUM('Verdieping 0'!H14:H15)*0.5*3.75 -> 0 | Q5: =SUM('Verdieping 0'!H30:H31)*0.5*3.75 -> 1593.75 | R5: =SUM('Verdieping 0'!H46:H47)*1.5*3.75 -> 843.75 | S5: =SUM('Verdieping 0'!M14:M15)*2.5*3.75 -> 7968.75 | T5: =SUM('Verdieping 0'!M30:M31)*3.5*3.75 -> 0 | W5: 7 | X5: =SUM('Verdieping -1'!C14:C15)*3.5*3.75 -> 0 | Y5: =SUM('Verdieping -1'!C30:C31)*2.5*3.75 -> 33142.09 | Z5: =SUM('Verdieping -1'!C46:C47)*1.5*3.75 -> 197.75391 | AA5: =SUM('Verdieping -1'!H14:H15)*0.5*3.75 -> 65.917969 | AB5: =SUM('Verdieping -1'!H30:H31)*0.5*3.75 -> 65.917969 | AC5: =SUM('Verdieping -1'!H46:H47)*1.5*3.75 -> 1322.7539 | AD5: =SUM('Verdieping -1'!M14:M15)*2.5*3.75 -> 18221.942 | AE5: =SUM('Verdieping -1'!M30:M31)*3.5*3.75 -> 0 | AH5: 7 | AI5: =SUM(B5,M5,X5) -> 0 | AJ5: =SUM(C5,N5,Y5) -> 18742.09 | AK5: =SUM(D5,O5,Z5) -> 4697.7539 | AL5: =SUM(E5,P5,AA5) -> 65.917969 | AM5: =SUM(F5,Q5,AB5) -> 1659.668 | AN5: =SUM(G5,R5,AC5) -> 2166.5039 | AO5: =SUM(H5,S5,AD5) -> 32167.254 | AP5: =SUM(I5,T5,AE5) -> 1698.0469
A6: 6 | B6: =SUM('Verdieping 1'!C12:C13)*3.5*3.75 -> 0 | C6: =SUM('Verdieping 1'!C28:C29)*2.5*3.75 -> 0 | D6: =SUM('Verdieping 1'!C44:C45)*1.5*3.75 -> 0 | E6: =SUM('Verdieping 1'!H12:H13)*0.5*3.75 -> 0 | F6: =SUM('Verdieping 1'!H28:H29)*0.5*3.75 -> 0 | G6: =SUM('Verdieping 1'!H44:H45)*1.5*3.75 -> 0 | H6: =SUM('Verdieping 1'!M12:M13)*2.5*3.75 -> 4804.6875 | I6: =SUM('Verdieping 1'!M28:M29)*3.5*3.75 -> 1698.0469 | L6: 6 | M6: =SUM('Verdieping 0'!C12:C13)*3.5*3.75 -> 0 | N6: =SUM('Verdieping 0'!C28:C29)*2.5*3.75 -> -35156.25 | O6: =SUM('Verdieping 0'!C44:C45)*1.5*3.75 -> 168.75 | P6: =SUM('Verdieping 0'!H12:H13)*0.5*3.75 -> 468.75 | Q6: =SUM('Verdieping 0'!H28:H29)*0.5*3.75 -> 1712.381 | R6: =SUM('Verdieping 0'!H44:H45)*1.5*3.75 -> 1968.75 | S6: =SUM('Verdieping 0'!M12:M13)*2.5*3.75 -> 7265.625 | T6: =SUM('Verdieping 0'!M28:M29)*3.5*3.75 -> 393.75 | W6: 6 | X6: =SUM('Verdieping -1'!C12:C13)*3.5*3.75 -> 0 | Y6: =SUM('Verdieping -1'!C28:C29)*2.5*3.75 -> 2673.3398 | Z6: =SUM('Verdieping -1'!C44:C45)*1.5*3.75 -> 3572.7539 | AA6: =SUM('Verdieping -1'!H12:H13)*0.5*3.75 -> 1190.918 | AB6: =SUM('Verdieping -1'!H28:H29)*0.5*3.75 -> 1190.918 | AC6: =SUM('Verdieping -1'!H44:H45)*1.5*3.75 -> 3572.7539 | AD6: =SUM('Verdieping -1'!M12:M13)*2.5*3.75 -> 1735.8398 | AE6: =SUM('Verdieping -1'!M28:M29)*3.5*3.75 -> 0 | AH6: 6 | AI6: =SUM(B6,M6,X6) -> 0 | AJ6: =SUM(C6,N6,Y6) -> -32482.91 | AK6: =SUM(D6,O6,Z6) -> 3741.5039 | AL6: =SUM(E6,P6,AA6) -> 1659.668 | AM6: =SUM(F6,Q6,AB6) -> 2903.299 | AN6: =SUM(G6,R6,AC6) -> 5541.5039 | AO6: =SUM(H6,S6,AD6) -> 13806.152 | AP6: =SUM(I6,T6,AE6) -> 2091.7969
A7: 5 | B7: =SUM('Verdieping 1'!C10:C11)*3.5*3.75 -> 0 | C7: =SUM('Verdieping 1'!C26:C27)*2.5*3.75 -> 0 | D7: =SUM('Verdieping 1'!C42:C43)*1.5*3.75 -> 0 | E7: =SUM('Verdieping 1'!H10:H11)*0.5*3.75 -> 0 | F7: =SUM('Verdieping 1'!H26:H27)*0.5*3.75 -> 0 | G7: =SUM('Verdieping 1'!H42:H43)*1.5*3.75 -> 0 | H7: =SUM('Verdieping 1'!M10:M11)*2.5*3.75 -> 468.75 | I7: =SUM('Verdieping 1'!M26:M27)*3.5*3.75 -> 3343.8986 | L7: 5 | M7: =SUM('Verdieping 0'!C10:C11)*3.5*3.75 -> 0 | N7: =SUM('Verdieping 0'!C26:C27)*2.5*3.75 -> 1875 | O7: =SUM('Verdieping 0'!C42:C43)*1.5*3.75 -> 20619.141 | P7: =SUM('Verdieping 0'!H10:H11)*0.5*3.75 -> 6966.7969 | Q7: =SUM('Verdieping 0'!H26:H27)*0.5*3.75 -> 7154.2969 | R7: =SUM('Verdieping 0'!H42:H43)*1.5*3.75 -> 0 | S7: =SUM('Verdieping 0'!M10:M11)*2.5*3.75 -> 34687.5 | T7: =SUM('Verdieping 0'!M26:M27)*3.5*3.75 -> 984.375 | W7: 5 | X7: =SUM('Verdieping -1'!C10:C11)*3.5*3.75 -> 0 | Y7: =SUM('Verdieping -1'!C26:C27)*2.5*3.75 -> 3750 | Z7: =SUM('Verdieping -1'!C42:C43)*1.5*3.75 -> 1968.75 | AA7: =SUM('Verdieping -1'!H10:H11)*0.5*3.75 -> 468.75 | AB7: =SUM('Verdieping -1'!H26:H27)*0.5*3.75 -> 937.5 | AC7: =SUM('Verdieping -1'!H42:H43)*1.5*3.75 -> 562.5 | AD7: =SUM('Verdieping -1'!M10:M11)*2.5*3.75 -> 4687.5 | AE7: =SUM('Verdieping -1'!M26:M27)*3.5*3.75 -> 0 | AH7: 5 | AI7: =SUM(B7,M7,X7) -> 0 | AJ7: =SUM(C7,N7,Y7) -> 5625 | AK7: =SUM(D7,O7,Z7) -> 22587.891 | AL7: =SUM(E7,P7,AA7) -> 7435.5469 | AM7: =SUM(F7,Q7,AB7) -> 8091.7969 | AN7: =SUM(G7,R7,AC7) -> 562.5 | AO7: =SUM(H7,S7,AD7) -> 39843.75 | AP7: =SUM(I7,T7,AE7) -> 4328.2736
A8: 4 | B8: =SUM('Verdieping 1'!C8:C9)*3.5*3.75 -> 0 | C8: =SUM('Verdieping 1'!C24:C25)*2.5*3.75 -> 0 | D8: =SUM('Verdieping 1'!C40:C41)*1.5*3.75 -> 0 | E8: =SUM('Verdieping 1'!H8:H9)*0.5*3.75 -> 0 | F8: =SUM('Verdieping 1'!H24:H25)*0.5*3.75 -> 0 | G8: =SUM('Verdieping 1'!H40:H41)*1.5*3.75 -> 104625 | H8: =SUM('Verdieping 1'!M8:M9)*2.5*3.75 -> 468.75 | I8: =SUM('Verdieping 1'!M24:M25)*3.5*3.75 -> 2682.4219 | L8: 4 | M8: =SUM('Verdieping 0'!C8:C9)*3.5*3.75 -> 0 | N8: =SUM('Verdieping 0'!C24:C25)*2.5*3.75 -> -14437.5 | O8: =SUM('Verdieping 0'!C40:C41)*1.5*3.75 -> 20337.891 | P8: =SUM('Verdieping 0'!H8:H9)*0.5*3.75 -> 7041.7969 | Q8: =SUM('Verdieping 0'!H24:H25)*0.5*3.75 -> 7266.7969 | R8: =SUM('Verdieping 0'!H40:H41)*1.5*3.75 -> 843.75 | S8: =SUM('Verdieping 0'!M8:M9)*2.5*3.75 -> 11250 | T8: =SUM('Verdieping 0'!M24:M25)*3.5*3.75 -> 0 | W8: 4 | X8: =SUM('Verdieping -1'!C8:C9)*3.5*3.75 -> 0 | Y8: =SUM('Verdieping -1'!C24:C25)*2.5*3.75 -> 30000 | Z8: =SUM('Verdieping -1'!C40:C41)*1.5*3.75 -> 1237.5 | AA8: =SUM('Verdieping -1'!H8:H9)*0.5*3.75 -> 0 | AB8: =SUM('Verdieping -1'!H24:H25)*0.5*3.75 -> 0 | AC8: =SUM('Verdieping -1'!H40:H41)*1.5*3.75 -> 0 | AD8: =SUM('Verdieping -1'!M8:M9)*2.5*3.75 -> 2343.75 | AE8: =SUM('Verdieping -1'!M24:M25)*3.5*3.75 -> 0 | AH8: 4 | AI8: =SUM(B8,M8,X8) -> 0 | AJ8: =SUM(C8,N8,Y8) -> 15562.5 | AK8: =SUM(D8,O8,Z8) -> 21575.391 | AL8: =SUM(E8,P8,AA8) -> 7041.7969 | AM8: =SUM(F8,Q8,AB8) -> 7266.7969 | AN8: =SUM(G8,R8,AC8) -> 105468.75 | AO8: =SUM(H8,S8,AD8) -> 14062.5 | AP8: =SUM(I8,T8,AE8) -> 2682.4219
A9: 3 | B9: =SUM('Verdieping 1'!C6:C7)*3.5*3.75 -> 0 | C9: =SUM('Verdieping 1'!C22:C23)*2.5*3.75 -> 0 | D9: =SUM('Verdieping 1'!C38:C39)*1.5*3.75 -> 0 | E9: =SUM('Verdieping 1'!H6:H7)*0.5*3.75 -> 0 | F9: =SUM('Verdieping 1'!H22:H23)*0.5*3.75 -> 0 | G9: =SUM('Verdieping 1'!H38:H39)*1.5*3.75 -> 0 | H9: =SUM('Verdieping 1'!M6:M7)*2.5*3.75 -> 5273.4375 | I9: =SUM('Verdieping 1'!M22:M23)*3.5*3.75 -> 1698.0469 | L9: 3 | M9: =SUM('Verdieping 0'!C6:C7)*3.5*3.75 -> 0 | N9: =SUM('Verdieping 0'!C22:C23)*2.5*3.75 -> -14437.5 | O9: =SUM('Verdieping 0'!C38:C39)*1.5*3.75 -> 13500 | P9: =SUM('Verdieping 0'!H6:H7)*0.5*3.75 -> 206.25 | Q9: =SUM('Verdieping 0'!H22:H23)*0.5*3.75 -> 3750 | R9: =SUM('Verdieping 0'!H38:H39)*1.5*3.75 -> 3937.5 | S9: =SUM('Verdieping 0'!M6:M7)*2.5*3.75 -> 11250 | T9: =SUM('Verdieping 0'!M22:M23)*3.5*3.75 -> 0 | W9: 3 | X9: =SUM('Verdieping -1'!C6:C7)*3.5*3.75 -> 0 | Y9: =SUM('Verdieping -1'!C22:C23)*2.5*3.75 -> 30468.75 | Z9: =SUM('Verdieping -1'!C38:C39)*1.5*3.75 -> 843.75 | AA9: =SUM('Verdieping -1'!H6:H7)*0.5*3.75 -> 187.5 | AB9: =SUM('Verdieping -1'!H22:H23)*0.5*3.75 -> 468.75 | AC9: =SUM('Verdieping -1'!H38:H39)*1.5*3.75 -> 1406.25 | AD9: =SUM('Verdieping -1'!M6:M7)*2.5*3.75 -> 3750 | AE9: =SUM('Verdieping -1'!M22:M23)*3.5*3.75 -> 0 | AH9: 3 | AI9: =SUM(B9,M9,X9) -> 0 | AJ9: =SUM(C9,N9,Y9) -> 16031.25 | AK9: =SUM(D9,O9,Z9) -> 14343.75 | AL9: =SUM(E9,P9,AA9) -> 393.75 | AM9: =SUM(F9,Q9,AB9) -> 4218.75 | AN9: =SUM(G9,R9,AC9) -> 5343.75 | AO9: =SUM(H9,S9,AD9) -> 20273.438 | AP9: =SUM(I9,T9,AE9) -> 1698.0469
A10: 2 | B10: =SUM('Verdieping 1'!C4:C5)*3.5*3.75 -> 1312.5 | C10: =SUM('Verdieping 1'!C20:C21)*2.5*3.75 -> 0 | D10: =SUM('Verdieping 1'!C36:C37)*1.5*3.75 -> 0 | E10: =SUM('Verdieping 1'!H4:H5)*0.5*3.75 -> 0 | F10: =SUM('Verdieping 1'!H20:H21)*0.5*3.75 -> 0 | G10: =SUM('Verdieping 1'!H36:H37)*1.5*3.75 -> 0 | H10: =SUM('Verdieping 1'!M4:M5)*2.5*3.75 -> 6562.5 | I10: =SUM('Verdieping 1'!M20:M21)*3.5*3.75 -> 1698.0469 | L10: 2 | M10: =SUM('Verdieping 0'!C4:C5)*3.5*3.75 -> 0 | N10: =SUM('Verdieping 0'!C20:C21)*2.5*3.75 -> 1875 | O10: =SUM('Verdieping 0'!C36:C37)*1.5*3.75 -> 843.75 | P10: =SUM('Verdieping 0'!H4:H5)*0.5*3.75 -> 0 | Q10: =SUM('Verdieping 0'!H20:H21)*0.5*3.75 -> 487.5 | R10: =SUM('Verdieping 0'!H36:H37)*1.5*3.75 -> 11812.5 | S10: =SUM('Verdieping 0'!M4:M5)*2.5*3.75 -> 3750 | T10: =SUM('Verdieping 0'!M20:M21)*3.5*3.75 -> 0 | W10: 2 | X10: =SUM('Verdieping -1'!C4:C5)*3.5*3.75 -> 0 | Y10: =SUM('Verdieping -1'!C20:C21)*2.5*3.75 -> 1406.25 | Z10: =SUM('Verdieping -1'!C36:C37)*1.5*3.75 -> 112.5 | AA10: =SUM('Verdieping -1'!H4:H5)*0.5*3.75 -> 187.5 | AB10: =SUM('Verdieping -1'!H20:H21)*0.5*3.75 -> 93.75 | AC10: =SUM('Verdieping -1'!H36:H37)*1.5*3.75 -> 9450 | AD10: =SUM('Verdieping -1'!M4:M5)*2.5*3.75 -> 937.5 | AE10: =SUM('Verdieping -1'!M20:M21)*3.5*3.75 -> 0 | AH10: 2 | AI10: =SUM(B10,M10,X10) -> 1312.5 | AJ10: =SUM(C10,N10,Y10) -> 3281.25 | AK10: =SUM(D10,O10,Z10) -> 956.25 | AL10: =SUM(E10,P10,AA10) -> 187.5 | AM10: =SUM(F10,Q10,AB10) -> 581.25 | AN10: =SUM(G10,R10,AC10) -> 21262.5 | AO10: =SUM(H10,S10,AD10) -> 11250 | AP10: =SUM(I10,T10,AE10) -> 1698.0469
A11: 1 | B11: =SUM('Verdieping 1'!C2:C3)*3.5*3.75 -> 14437.5 | C11: =SUM('Verdieping 1'!C18:C19)*2.5*3.75 -> 0 | D11: =SUM('Verdieping 1'!C34:C35)*1.5*3.75 -> 7312.5 | E11: =SUM('Verdieping 1'!H2:H3)*0.5*3.75 -> 0 | F11: =SUM('Verdieping 1'!H18:H19)*0.5*3.75 -> 0 | G11: =SUM('Verdieping 1'!H34:H35)*1.5*3.75 -> 0 | H11: =SUM('Verdieping 1'!M2:M3)*2.5*3.75 -> 0 | I11: =SUM('Verdieping 1'!M18:M19)*3.5*3.75 -> 1698.0469 | L11: 1 | M11: =SUM('Verdieping 0'!C2:C3)*3.5*3.75 -> 0 | N11: =SUM('Verdieping 0'!C18:C19)*2.5*3.75 -> 0 | O11: =SUM('Verdieping 0'!C34:C35)*1.5*3.75 -> 0 | P11: =SUM('Verdieping 0'!H2:H3)*0.5*3.75 -> 0 | Q11: =SUM('Verdieping 0'!H18:H19)*0.5*3.75 -> 0 | R11: =SUM('Verdieping 0'!H34:H35)*1.5*3.75 -> 5625 | S11: =SUM('Verdieping 0'!M2:M3)*2.5*3.75 -> 1218.75 | T11: =SUM('Verdieping 0'!M18:M19)*3.5*3.75 -> 0 | W11: 1 | X11: =SUM('Verdieping -1'!C2:C3)*3.5*3.75 -> 0 | Y11: =SUM('Verdieping -1'!C18:C19)*2.5*3.75 -> 0 | Z11: =SUM('Verdieping -1'!C34:C35)*1.5*3.75 -> 0 | AA11: =SUM('Verdieping -1'!H2:H3)*0.5*3.75 -> 0 | AB11: =SUM('Verdieping -1'!H18:H19)*0.5*3.75 -> 0 | AC11: =SUM('Verdieping -1'!H34:H35)*1.5*3.75 -> 0 | AD11: =SUM('Verdieping -1'!M2:M3)*2.5*3.75 -> 0 | AE11: =SUM('Verdieping -1'!M18:M19)*3.5*3.75 -> 0 | AH11: 1 | AI11: =SUM(B11,M11,X11) -> 14437.5 | AJ11: =SUM(C11,N11,Y11) -> 0 | AK11: =SUM(D11,O11,Z11) -> 7312.5 | AL11: =SUM(E11,P11,AA11) -> 0 | AM11: =SUM(F11,Q11,AB11) -> 0 | AN11: =SUM(G11,R11,AC11) -> 5625 | AO11: =SUM(H11,S11,AD11) -> 1218.75 | AP11: =SUM(I11,T11,AE11) -> 1698.0469
B12: A | C12: B | D12: C | E12: D | F12: E | G12: F | H12: G | I12: H | J12: I | M12: A | N12: B | O12: C | P12: D | Q12: E | R12: F | S12: G | T12: H | U12: I | X12: A | Y12: B | Z12: C | AA12: D | AB12: E | AC12: F | AD12: G | AE12: H | AF12: I | AI12: A | AJ12: B | AK12: C | AL12: D | AM12: E | AN12: F | AO12: G | AP12: H | AQ12: I | AW12: 𝑉 = 𝑔 ⋅ 𝜌/(𝑀⋅ 𝑠)
AP13: kg*m | AR13: N*m | AS13: Moment abs (Nm) | AT13: arm tot middelpunt van tank(m) | AU13: dichtheidvloeistof (kg/m³) | AV13: zwaartekracht (N) | AW13: volume tank (m³)
B14: =SUM(B4:E11) -> 34331.629 | I14: =SUM(F4:I11) -> 142538.42 | M14: =SUM(M4:P11) -> 9346.875 | T14: =SUM(Q4:T11) -> 125764.72 | X14: =SUM(X4:AA11) -> 111474.02 | AE14: =SUM(AB4:AE11) -> 50747.625 | AO14: Totaal moment linkerhelft | AP14: =SUM(B14,M14,X14) -> 155152.53 | AR14: =AP14*AO$21 -> 1521526.5 | AS14: =ABS(AR$16) -> 1607292.7 | AT14: 1 | AU14: 997 | AV14: 9.81 | AW14: =AS14/(AV14*AU14*AT14) -> 164.33528
AO15: Totaal moment rechterhelft | AP15: =SUM(I14,T14,AE14) -> 319050.77 | AR15: =AP15*AO$21 -> 3128819.2 | AS15: =ABS(AR$16) -> 1607292.7 | AT15: =AT14+1 -> 2 | AU15: 997 | AV15: 9.81 | AW15: =AS15/(AV15*AU15*AT15) -> 82.167639
AO16: Totaal moment verschil | AP16: =AP14-AP15 -> -163898.24 | AR16: =AP16*AO$21 -> -1607292.7 | AS16: =ABS(AR$16) -> 1607292.7 | AT16: =AT15+1 -> 3 | AU16: 997 | AV16: 9.81 | AW16: =AS16/(AV16*AU16*AT16) -> 54.778426
AO17: Pos waarde betekend meer gewicht linkerhelft | AS17: =ABS(AR$16) -> 1607292.7 | AT17: =AT16+1 -> 4 | AU17: 997 | AV17: 9.81 | AW17: =AS17/(AV17*AU17*AT17) -> 41.083819
AS18: =ABS(AR$16) -> 1607292.7 | AT18: =AT17+1 -> 5 | AU18: 997 | AV18: 9.81 | AW18: =AS18/(AV18*AU18*AT18) -> 32.867055
AS19: =ABS(AR$16) -> 1607292.7 | AT19: =AT18+1 -> 6 | AU19: 997 | AV19: 9.81 | AW19: =AS19/(AV19*AU19*AT19) -> 27.389213
AO20: 1 kg*m to 1 N*m | AS20: =ABS(AR$16) -> 1607292.7 | AT20: =AT19+1 -> 7 | AU20: 997 | AV20: 9.81 | AW20: =AS20/(AV20*AU20*AT20) -> 23.476468
AO21: 9.80665 | AS21: =ABS(AR$16) -> 1607292.7 | AT21: =AT20+1 -> 8 | AU21: 997 | AV21: 9.81 | AW21: =AS21/(AV21*AU21*AT21) -> 20.54191
AS22: =ABS(AR$16) -> 1607292.7 | AT22: =AT21+1 -> 9 | AU22: 997 | AV22: 9.81 | AW22: =AS22/(AV22*AU22*AT22) -> 18.259475
AS23: =ABS(AR$16) -> 1607292.7 | AT23: =AT22+1 -> 10 | AU23: 997 | AV23: 9.81 | AW23: =AS23/(AV23*AU23*AT23) -> 16.433528
AM24: 𝐹 = 𝜌 ⋅ 𝑉 ⋅ 𝑔 | AO24: 𝑉 = 𝐹/𝑔 ⋅ 𝜌 | AS24: =ABS(AR$16) -> 1607292.7 | AT24: =AT23+1 -> 11 | AU24: 997 | AV24: 9.81 | AW24: =AS24/(AV24*AU24*AT24) -> 14.939571
AM25: Waarin: | AS25: =ABS(AR$16) -> 1607292.7 | AT25: =AT24+1 -> 12 | AU25: 997 | AV25: 9.81 | AW25: =AS25/(AV25*AU25*AT25) -> 13.694606
AM26: F: opwaartse kracht [N] | AS26: =ABS(AR$16) -> 1607292.7 | AT26: =AT25+1 -> 13 | AU26: 997 | AV26: 9.81 | AW26: =AS26/(AV26*AU26*AT26) -> 12.641175
AM27: ρ: dichtheid van de vloeistof [kg/m³] | AS27: =ABS(AR$16) -> 1607292.7 | AT27: =AT26+1 -> 14 | AU27: 997 | AV27: 9.81 | AW27: =AS27/(AV27*AU27*AT27) -> 11.738234
AM28: V: volume van de verplaatste vloeistof [m³] | AS28: =ABS(AR$16) -> 1607292.7 | AT28: =AT27+1 -> 15 | AU28: 997 | AV28: 9.81 | AW28: =AS28/(AV28*AU28*AT28) -> 10.955685
AM29: g: gravitatieversnelling [N]
AM31: 𝑀 = 𝐹 ⋅ 𝑠 | AN31: 𝐹 = 𝑀⋅ 𝑠
AM32: Waarin de symbolen de volgende betekenis hebben:
AM33: M = het moment [Nm]
AM34: F = de kracht (het gewicht per raster vak) [N]
AM35: s = de arm [m]

Sheet groote schaal model
A1: formaat beton blok
B3: grote schaal model (cm) | C3: grote floating farm (m) | D3: grote floating farm (cm) | F3: ration
A4: hoogte | B4: 6.4 | C4: 5.2 | D4: =C4*100 -> 520
A5: breed | B5: 30 | C5: 30 | D5: =C5*100 -> 3000
A6: lengthe | B6: 30 | C6: 30 | D6: =C6*100 -> 3000
B7: cm^3 | C7: m^3 | D7: cm^3 | F7: =D8/B8 -> 812500
A8: volume | B8: =B4*B5*B6 -> 5760 | C8: =C4*C5*C6 -> 4680 | D8: =D4*D5*D6 -> 4680000000
A9: drijf tank volume | B9: =D9/F7 -> 11.076923 | C9: 9 | D9: =C9*1000000 -> 9000000
